<?xml version="1.0"?>
<robot xmlns:xacro="http://www.ros.org/wiki/xacro" name="manipulator">

    <xacro:arg name="is_ignition" default="true"/>   <!-- Ignition simulation flag is used to enable/disable ignition features -->
    <!-- Often you need to include different plugin tags, different frames, or different element names depending on whether you run 
     the model in Ignition (which changed some plugin names & SDF behavior) or in classic Gazebo. The is_ignition arg lets you 
     switch between those variants without maintaining two separate files.-->


    <xacro:include filename="$(find manipulator_description)/urdf/manipulator_gazebo.xacro"/>
    <xacro:include filename="$(find manipulator_description)/urdf/manipulator_ros2_control.xacro"/>
    
    <!-- Useful XACRO Variables (Properties) -->
    <xacro:property name="PI" value="3.14159265359" />
    <xacro:property name="effort" value="30.0" />
    <xacro:property name="velocity" value="10.0" />

    <!-- Useful Macros -->
    <xacro:macro name="default_inertial" params="mass">
        <inertial>
            <origin xyz="0 0 0" rpy="0 0 0"/>
            <mass value="${mass}" />
            <inertia ixx="1.0" ixy="0.0" ixz="0.0"
                     iyy="1.0" iyz="0.0"
                     izz="1.0" />
        </inertial>
    </xacro:macro>

    <!-- Shared materials (RGBA, values 0..1) -->
    <material name="mat_base">
        <color rgba="0.0 0.2 0.8 1.0"/>   <!-- blue -->
    </material>
    <material name="mat_plate">
        <color rgba="0.8 0.1 0.1 1.0"/>   <!-- red -->
    </material>
    <material name="mat_arm1">
        <color rgba="0.1 0.8 0.2 1.0"/>   <!-- green -->
    </material>
    <material name="mat_arm2">
        <color rgba="0.95 0.6 0.15 1.0"/> <!-- orange -->
    </material>
    <material name="mat_claw">
        <color rgba="0.6 0.2 0.8 1.0"/>   <!-- purple -->
    </material>
    <material name="mat_gripper">
        <color rgba="0.95 0.92 0.15 1.0"/><!-- yellow -->
    </material>
    <material name="mat_mesh_grey">
        <color rgba="0.5 0.5 0.5 1.0"/>   <!-- fallback grey -->
    </material>

    <!-- Links -->
    <link name="world"/>

    <link name="base_link">
        <xacro:default_inertial mass="1.0"/>
        <visual>
            <origin rpy="0 0 0" xyz="-0.5 -0.5 0"/>    
            <geometry>
                <mesh filename="package://manipulator_description/meshes/basement.STL" scale="0.01 0.01 0.01"/>
            </geometry>
            <material name="mat_base"/>
        </visual>
        <collision>
            <origin rpy="0 0 0" xyz="-0.5 -0.5 0"/>
            <geometry>
                <mesh filename="package://manipulator_description/meshes/basement.STL" scale="0.01 0.01 0.01"/>
            </geometry>
        </collision>
    </link>

    <joint name="virtual_joint" type="fixed">
        <parent link="world"/>
        <child link="base_link"/>
        <origin xyz="0 0 0" rpy="0 0 0"/>
    </joint> 

    <link name="base_plate">
        <xacro:default_inertial mass="0.1"/>
        <visual>
            <origin rpy="0 0 0" xyz="-0.39 -0.39 -0.56"/>    <!-- Every link has a link frame (its origin, usually at the center or a meaningful point). Here that point is at parent's origin -->
            <geometry>
                <mesh filename="package://manipulator_description/meshes/base_plate.STL" scale="0.01 0.01 0.01"/>
            </geometry>
            <material name="mat_plate"/>
        </visual>
        <collision>
            <origin rpy="0 0 0" xyz="-0.39 -0.39 -0.56"/>   <!-- pose of the child link frame relative to the parent link frame. -->
            <geometry>
                <mesh filename="package://manipulator_description/meshes/base_plate.STL" scale="0.01 0.01 0.01"/>
            </geometry>
        </collision>
    </link>

     <joint name ="joint_1" type="revolute">
        <parent link="base_link"/>
        <child link = "base_plate"/>
        <origin xyz="0 0 0.307"/>
        <axis xyz="0 0 1"/>
        <limit lower="-${PI / 2}" upper="${PI / 2}" 
               effort="${effort}" velocity="${velocity}"/>
    </joint>

    <link name="forward_drive_arm">
        <xacro:default_inertial mass="0.1"/>
        <visual>
            <origin rpy=" 0 -${PI / 2} ${PI / 2}" xyz="0.19 0.06 -0.08"/>
            <geometry>
                <mesh filename="package://manipulator_description/meshes/forward_drive_arm.STL" scale="0.01 0.01 0.01"/>
            </geometry>
            <material name="mat_arm1"/>
        </visual>
        <collision>
            <origin rpy=" 0 -${PI / 2} ${PI / 2}" xyz="0.19 0.06 -0.08"/>
            <geometry>
                <mesh filename="package://manipulator_description/meshes/forward_drive_arm.STL" scale="0.01 0.01 0.01"/>
            </geometry>
        </collision>
    </link>

    <joint name ="joint_2" type="revolute">
        <parent link="base_plate"/>
        <child link = "forward_drive_arm"/>
        <origin xyz="-0.02 0 0.35"/>
        <axis xyz="1 0 0"/>
        <limit lower="-${PI / 2}" upper="${PI / 2}"
                effort="${effort}" velocity="${velocity}"/>
    </joint>

    <link name="horizontal_arm">
        <xacro:default_inertial mass="0.1"/>
        <visual>
            <origin rpy="${PI / 2} 0 ${PI / 2}" xyz="-0.03 -0.4 -0.06"/>
            <geometry>
                <mesh filename="package://manipulator_description/meshes/horizontal_arm.STL" scale="0.01 0.01 0.01"/>
            </geometry>
            <material name="mat_arm2"/>
        </visual>
        <collision>
            <origin rpy="${PI / 2} 0 ${PI / 2}" xyz="-0.03 -0.4 -0.06"/>
            <geometry>
                <mesh filename="package://manipulator_description/meshes/horizontal_arm.STL" scale="0.01 0.01 0.01"/>
            </geometry>
        </collision>
    </link>

    <joint name ="joint_3" type="revolute">
        <parent link="forward_drive_arm"/>
        <child link = "horizontal_arm"/>
        <origin xyz="0 0 0.8"/>
        <axis xyz="1 0 0"/>
        <limit lower="-${PI / 2}" upper="${PI / 2}"
               effort="${effort}" velocity="${velocity}"/>
    </joint>

    <link name="claw_support">
        <xacro:default_inertial mass="0.05"/>
        <visual>
            <origin rpy="0 0 ${PI / 2}" xyz="0 -0.05 -0.15"/>
            <geometry>
                <mesh filename="package://manipulator_description/meshes/claw_support.STL" scale="0.01 0.01 0.01"/>
            </geometry>
            <material name="mat_claw"/>
        </visual>
        <collision>
            <origin rpy="0 0 ${PI / 2}" xyz="0 -0.05 -0.15"/>
            <geometry>
                <mesh filename="package://manipulator_description/meshes/claw_support.STL" scale="0.01 0.01 0.01"/>
            </geometry>
        </collision>
    </link>

    <joint name ="horizontal_arm_to_claw_support" type="fixed">
        <parent link="horizontal_arm"/>
        <child link = "claw_support"/>
        <origin xyz="0 0.82 0"/>
    </joint>

    <link name="gripper_right">
        <xacro:default_inertial mass="0.01"/>
        <visual>
            <origin rpy="0 0 -${PI / 2}" xyz="-0.1 0.50 -0.1"/>
            <geometry>
                <mesh filename="package://manipulator_description/meshes/right_finger.STL" scale="0.01 0.01 0.01"/>
            </geometry>
            <material name="mat_gripper"/>
        </visual>
        <collision>
            <origin rpy="0 0 -${PI / 2}" xyz="-0.1 0.50 -0.1"/>
            <geometry>
                <mesh filename="package://manipulator_description/meshes/right_finger.STL" scale="0.01 0.01 0.01"/>
            </geometry>
        </collision>
    </link>

    <joint name ="joint_4" type="revolute">
        <parent link="claw_support"/>
        <child link = "gripper_right"/>
        <origin xyz="-0.04 0.13 -0.1"/>
        <axis xyz="0 0 1"/>
        <limit lower="-${PI / 2}" upper="0.0" 
               effort="${effort}" velocity="${velocity}"/>
        <dynamics damping="0.001" friction="0.001"/>
    </joint>

    <link name="gripper_left">
        <xacro:default_inertial mass="0.01"/>
        <visual>
            <origin rpy="0 0 -${PI / 2}" xyz="-0.04 0.50 -0.1"/>
            <geometry>
                <mesh filename="package://manipulator_description/meshes/left_finger.STL" scale="0.01 0.01 0.01"/>
            </geometry>
            <material name="mat_gripper"/>
        </visual>
        <collision>
            <origin rpy="0 0 -${PI / 2}" xyz="-0.04 0.50 -0.1"/>
            <geometry>
                <mesh filename="package://manipulator_description/meshes/left_finger.STL" scale="0.01 0.01 0.01"/>
            </geometry>
        </collision>
    </link>

    <joint name ="joint_5" type="revolute">
        <parent link="claw_support"/>
        <child link = "gripper_left"/>
        <origin xyz="-0.22 0.13 -0.1"/>
        <axis xyz="0 0 1"/>
        <limit lower="0.0" upper="${PI / 2}" 
               effort="${effort}" velocity="${velocity}"/>
        <dynamics damping="0.001" friction="0.001"/>
        <mimic joint="joint_4" multiplier="-1"/>   <!-- This joint mimics joint_4 means it will move in the opposite direction to joint_4 -->
    </joint>

    
</robot>
